<?xml version="1.0" ?>
<!-- =================================================================================== -->
<!-- |    This document was autogenerated by xacro from vision60.urdf.xacro            | -->
<!-- |    Converted by Wen-Loong Ma, 2018-08-04, Caltech                               | -->
<!-- |    Toe deleted                                                                  | -->
<!-- |    Meshes added                                                                 | -->
<!-- |    EDITING THIS FILE BY HAND IS NOT RECOMMENDED                                 | -->
<!-- =================================================================================== -->
<!--
 * Copyright (C) Ghost Robotics - All Rights Reserved
 * Unauthorized copying of this file, via any medium is strictly prohibited
 * Proprietary and confidential
 * Written by Avik De <avik@ghostrobotics.io> and Tom Jacobs <tom.jacobs@ghostrobotics.io>
-->
<robot name="vision60" xmlns:xacro="http://www.ros.org/wiki/xacro">
  <!-- Define materials -->
  <material name="gray">
    <color rgba="0.5 0.5 0.5 1.2"/>
  </material>
  <material name="white">
    <color rgba="1 1 1 0.9"/>
  </material>
  <material name="darkgray">
    <color rgba="0.3 0.3 0.3 1.0"/>
  </material>
  <material name="blue">
    <color rgba="0 0 0.8 1"/>
  </material>
  <material name="black">
    <color rgba="0 0 0 1"/>
  </material>
  <material name="purple">
    <color rgba="0.5 0.0 0.5 1.0"/>
  </material>
  <material name="red">
    <color rgba="0.8 0.0 0.2 1.0"/>
  </material>
  <material name="ctorange">
    <color rgba="1.0 0.43137254902 0.117647058824 1"/>
  </material>
  <!-- Body -->
  <link name="body">
    <visual>
      <origin rpy="0 0 0" xyz="-0.45 -0.155  -0.105"/>
      <geometry>
        <!-- <box size="0.88 0.25 0.19"/> -->
        <mesh scale="0.001 0.001 0.001" filename="package://vision60/meshes/body_frame.STL"/>
      </geometry>
      <material name="darkgray"/>
    </visual>
    <inertial>
      <mass value="12"/>
      <!-- Uniform box -->
      <inertia ixx="0.058" ixy="0" ixz="0" iyy="0.149" iyz="0" izz="0.195"/>
    </inertial>
    <!-- Just copy geometry for collision -->
    <collision>
      <geometry>
        <!-- <box size="0.05 0.25 0.19"/> -->
        <mesh filename="package://vision60/meshes/body_frame.STL"/>
      </geometry>
    </collision>
  </link>
  <!-- red new legs -->
  <!-- TODO: clean this, it should be part of main leg macro -->
  <!-- Hip motor -->
  <link name="hip0">
    <visual>
      <origin rpy="0 3.1415926 0" xyz="0.095 -0.1232 0.0487"/>
      <geometry>
        <mesh scale="0.001 0.001 0.001" filename="package://vision60/meshes/motor_lh.STL"/>
	      <!-- <box size="0.195 0.1 0.17"/> -->
      </geometry>
      <material name="gray"/>
    </visual>
    <collision>
      <origin rpy="1.5707963268 0 0" xyz="0.0 -0.039 0"/>
      <geometry>
	   <mesh filename="package://vision60/meshes/motor_lh.STL"/>
        <!-- <box size="0.195 0.1 0.17"/> -->
      </geometry>
    </collision>
    <inertial>
      <mass value="2.75"/>
      <inertia ixx="0.0058" ixy="0" ixz="0" iyy="0.0058" iyz="0" izz="0.0027"/>
    </inertial>
  </link>
  <!-- Abduction joint. Joint names are: 8 9 10 11 -->
  <joint name="hipRoll0" type="revolute">
    <parent link="body"/>
    <child link="hip0"/>
    <axis xyz="1 0 0"/>
    <origin xyz="0.325 0.1575 0"/>
    <limit effort="375" lower="-0.43" upper="0.43" velocity="8.6"/>
    <dynamics damping="0.0" friction="0.0"/>
  </joint>
  <!-- Upper leg -->
  <link name="upper0">
    <visual>
      <origin rpy="3.1415926 1.5707963 3.1415926" xyz="-0.27 -0.07 0.05"/>
      <!--<origin rpy="0 0 0" xyz="-0.125 0.0 0"/>-->
      <geometry>
        <mesh scale="0.001 0.001 0.001" filename="package://vision60/meshes/femur.STL"/>
        <!--<box size="0.25 0.044 0.06"/>-->
      </geometry>
      <material name="ctorange"/>
    </visual>
    <collision>
      <origin rpy="0 0 0" xyz="-0.125 0 0"/>
      <geometry>
        <box size="0.25 0.044 0.06"/>
      </geometry>
    </collision>
    <inertial>
      <mass value="0.625"/>
      <inertia ixx="0.0003125" ixy="0" ixz="0" iyy="0.0040625" iyz="0" izz="0.0040625"/>
    </inertial>
  </link>
  <!-- Hip joint. (Motor to upper leg). Joint names are: 0 2 4 6 -->
  <joint name="hipPitch0" type="revolute">
    <parent link="hip0"/>
    <child link="upper0"/>
    <axis xyz="0 -1 0"/>
    <origin xyz="0 0.068 0"/>
    <!--  rpy="0 -0.3 0" -->
    <limit effort="87.5" lower="-3.14159265359" upper="3.14159265359" velocity="30"/>
    <dynamics damping="0.0" friction="0.0"/>
  </joint>
  <!-- Lower leg -->
  <link name="lower0">
    <visual>
      <!-- <origin rpy="0 1.5707963268 3.1415926" xyz="0.2 0.034 0.05"/> -->
      <origin rpy="0 -1.5707963268 0" xyz="0.29 -0.057  -0.02"/>
      <geometry>
        <mesh scale="0.001 0.001 0.001" filename="package://vision60/meshes/tibia.STL"/>
        <!--  <cylinder length="0.28" radius="0.011"/>  -->
      </geometry>
      <material name="darkgray"/>
    </visual>
    <collision>
      <origin rpy="0 1.5707963268 0" xyz="0.14 0 -0.0355"/>
      <geometry>
        <cylinder length="0.28" radius="0.011"/>
      </geometry>
    </collision>
    <inertial>
      <mass value="0.2"/>
      <inertia ixx="0.00131075" ixy="0" ixz="0" iyy="0.00131075" iyz="0" izz="0.0001"/>
    </inertial>
  </link>
  <!-- Knee joint. Joint names are: 1 3 5 7 -->
  <joint name="knee0" type="revolute">
    <parent link="upper0"/>
    <child link="lower0"/>
    <axis xyz="0 1 0"/>
    <origin xyz="-0.25 0 0"/>
    <!--rpy="0 0.5 0"-->
    <limit effort="87.5" lower="0" upper="3.14159265359" velocity="30"/>
    <dynamics damping="0.0" friction="0.0"/>
  </joint>
   <!-- Hip motor -->
  <link name="hip1">
    <visual>
      <!-- <origin rpy="1.5707963268 0 0" xyz="0.0 -0.039 0"/> -->
      <origin rpy="0 0 0" xyz="-0.112 -0.124 -0.055"/>
      <geometry>
        <mesh scale="0.001 0.001 0.001" filename="package://vision60/meshes/motor_lh.STL"/>
        <!-- <box size="0.195 0.1 0.17"/> -->
      </geometry>
      <material name="gray"/>
    </visual>
    <collision>
      <origin rpy="1.5707963268 0 0" xyz="0.0 -0.039 0"/>
      <geometry>
        <box size="0.195 0.1 0.17"/>
      </geometry>
    </collision>
    <inertial>
      <mass value="2.75"/>
      <inertia ixx="0.0058" ixy="0" ixz="0" iyy="0.0058" iyz="0" izz="0.0027"/>
    </inertial>
  </link>
  <!-- Abduction joint. Joint names are: 8 9 10 11 -->
  <joint name="hipRoll1" type="revolute">
    <parent link="body"/>
    <child link="hip1"/>
    <axis xyz="1 0 0"/>
    <origin xyz="-0.325 0.1575 0"/>
    <limit effort="375" lower="-0.43" upper="0.43" velocity="8.6"/>
    <dynamics damping="0.0" friction="0.0"/>
  </joint>
  <!-- Upper leg -->
  <link name="upper1">
    <visual>
      <origin rpy="3.1415926 1.5707963 3.1415926" xyz="-0.27 -0.07 0.05"/>
      <!-- <origin rpy="0 0 0" xyz="-0.125 0.0 0"/> -->
      <geometry>
        <mesh scale="0.001 0.001 0.001" filename="package://vision60/meshes/femur.STL"/>
        <!-- <box size="0.25 0.044 0.06"/> -->
      </geometry>
      <material name="ctorange"/>
    </visual>
    <collision>
      <origin rpy="0 0 0" xyz="-0.125 0 0"/>
      <geometry>
        <box size="0.25 0.044 0.06"/>
      </geometry>
    </collision>
    <inertial>
      <mass value="0.625"/>
      <inertia ixx="0.0003125" ixy="0" ixz="0" iyy="0.0040625" iyz="0" izz="0.0040625"/>
    </inertial>
  </link>
  <!-- Hip joint. (Motor to upper leg). Joint names are: 0 2 4 6 -->
  <joint name="hipPitch1" type="revolute">
    <parent link="hip1"/>
    <child link="upper1"/>
    <axis xyz="0 -1 0"/>
    <origin xyz="0 0.068 0"/>
    <!--  rpy="0 -0.3 0" -->
    <limit effort="87.5" lower="-3.14159265359" upper="3.14159265359" velocity="30"/>
    <dynamics damping="0.0" friction="0.0"/>
  </joint>
  <!-- Lower leg -->
  <link name="lower1">
    <visual>
      <origin rpy="0 -1.5707963268 0" xyz="0.29 -0.057  -0.02"/>
      <!-- <origin rpy="0 1.5707963268 0" xyz="0.14 0 -0.0355"/> -->
      <geometry>
        <mesh scale="0.001 0.001 0.001" filename="package://vision60/meshes/tibia.STL"/>
        <!-- <cylinder length="0.28" radius="0.011"/> -->
      </geometry>
      <material name="darkgray"/>
    </visual>
    <collision>
      <origin rpy="0 1.5707963268 0" xyz="0.14 0 -0.0355"/>
      <geometry>
        <cylinder length="0.28" radius="0.011"/>
      </geometry>
    </collision>
    <inertial>
      <mass value="0.2"/>
      <inertia ixx="0.00131075" ixy="0" ixz="0" iyy="0.00131075" iyz="0" izz="0.0001"/>
    </inertial>
  </link>
  <!-- Knee joint. Joint names are: 1 3 5 7 -->
  <joint name="knee1" type="revolute">
    <parent link="upper1"/>
    <child link="lower1"/>
    <axis xyz="0 1 0"/>
    <origin xyz="-0.25 0 0"/>
    <!--rpy="0 0.5 0"-->
    <limit effort="87.5" lower="0" upper="3.14159265359" velocity="30"/>
    <dynamics damping="0.0" friction="0.0"/>
  </joint>
  <!-- Hip motor -->
  <link name="hip2">
    <visual>
      <origin rpy="0 0 3.1415926" xyz="0.0916 0.122 -0.053"/>
      <!--<origin rpy="1.5707963268 0 0" xyz="0.0 0.039 0"/> -->
      <geometry>
        <mesh scale="0.001 0.001 0.001" filename="package://vision60/meshes/motor_lh.STL"/>
        <!-- <box size="0.195 0.1 0.17"/> -->
      </geometry>
      <material name="gray"/>
    </visual>
    <collision>
      <origin rpy="1.5707963268 0 0" xyz="0.0 0.039 0"/>
      <geometry>
        <box size="0.195 0.1 0.17"/>
      </geometry>
    </collision>
    <inertial>
      <mass value="2.75"/>
      <inertia ixx="0.0058" ixy="0" ixz="0" iyy="0.0058" iyz="0" izz="0.0027"/>
    </inertial>
  </link>
  <!-- Abduction joint. Joint names are: 8 9 10 11 -->
  <joint name="hipRoll2" type="revolute">
    <parent link="body"/>
    <child link="hip2"/>
    <axis xyz="1 0 0"/>
    <origin xyz="0.325 -0.1575 0"/>
    <limit effort="375" lower="-0.43" upper="0.43" velocity="8.6"/>
    <dynamics damping="0.0" friction="0.0"/>
  </joint>
  <!-- Upper leg -->
  <link name="upper2">
    <visual>
      <origin rpy="3.14 1.57 3.14" xyz="-0.27 -0.01 0.05"/>
      <!-- <origin rpy="0 0 0" xyz="-0.125 -0.0 0"/> -->
      <geometry>
        <mesh scale="0.001 0.001 0.001" filename="package://vision60/meshes/femur_rs.STL"/>
        <!-- <box size="0.25 0.044 0.06"/> -->
      </geometry>
      <material name="ctorange"/>
    </visual>
    <collision>
      <origin rpy="0 0 0" xyz="-0.125 0 0"/>
      <geometry>
        <box size="0.25 0.044 0.06"/>
      </geometry>
    </collision>
    <inertial>
      <mass value="0.625"/>
      <inertia ixx="0.0003125" ixy="0" ixz="0" iyy="0.0040625" iyz="0" izz="0.0040625"/>
    </inertial>
  </link>
  <!-- Hip joint. (Motor to upper leg). Joint names are: 0 2 4 6 -->
  <joint name="hipPitch2" type="revolute">
    <parent link="hip2"/>
    <child link="upper2"/>
    <axis xyz="0 -1 0"/>
    <origin xyz="0 -0.068 0"/>
    <!--  rpy="0 -0.3 0" -->
    <limit effort="87.5" lower="-3.14159265359" upper="3.14159265359" velocity="30"/>
    <dynamics damping="0.0" friction="0.0"/>
  </joint>
  <!-- Lower leg -->
  <link name="lower2">
    <visual>
      <origin rpy="0 -1.5707963268 0" xyz="0.29 0.02  -0.02"/>
      <!-- <origin rpy="0 1.5707963268 0" xyz="0.14 0 -0.0355"/> -->
      <geometry>
        <mesh scale="0.001 0.001 0.001" filename="package://vision60/meshes/tibia.STL"/>
        <!-- <cylinder length="0.28" radius="0.011"/> -->
      </geometry>
      <material name="darkgray"/>
    </visual>
    <collision>
      <origin rpy="0 1.5707963268 0" xyz="0.14 0 -0.0355"/>
      <geometry>
        <cylinder length="0.28" radius="0.011"/>
      </geometry>
    </collision>
    <inertial>
      <mass value="0.2"/>
      <inertia ixx="0.00131075" ixy="0" ixz="0" iyy="0.00131075" iyz="0" izz="0.0001"/>
    </inertial>
  </link>
  <!-- Knee joint. Joint names are: 1 3 5 7 -->
  <joint name="knee2" type="revolute">
    <parent link="upper2"/>
    <child link="lower2"/>
    <axis xyz="0 1 0"/>
    <origin xyz="-0.25 0 0"/>
    <!--rpy="0 0.5 0"-->
    <limit effort="87.5" lower="0" upper="3.14159265359" velocity="30"/>
    <dynamics damping="0.0" friction="0.0"/>
  </joint>
   <!-- Hip motor -->
  <link name="hip3">
    <visual>
      <origin rpy="3.1415926 0 0" xyz="-0.11 0.123 0.045"/>
      <!-- <origin rpy="1.5707963268 0 0" xyz="0.0 0.039 0"/> -->
      <geometry>
        <mesh scale="0.001 0.001 0.001" filename="package://vision60/meshes/motor_lh.STL"/>
        <!-- <box size="0.195 0.1 0.17"/> -->
      </geometry>
      <material name="gray"/>
    </visual>
    <collision>
      <origin rpy="1.5707963268 0 0" xyz="0.0 0.039 0"/>
      <geometry>
        <box size="0.195 0.1 0.17"/>
      </geometry>
    </collision>
    <inertial>
      <mass value="2.75"/>
      <inertia ixx="0.0058" ixy="0" ixz="0" iyy="0.0058" iyz="0" izz="0.0027"/>
    </inertial>
  </link>
  <!-- Abduction joint. Joint names are: 8 9 10 11 -->
  <joint name="hipRoll3" type="revolute">
    <parent link="body"/>
    <child link="hip3"/>
    <axis xyz="1 0 0"/>
    <origin xyz="-0.325 -0.1575 0"/>
    <limit effort="375" lower="-0.43" upper="0.43" velocity="8.6"/>
    <dynamics damping="0.0" friction="0.0"/>
  </joint>
  <!-- Upper leg -->
  <link name="upper3">
    <visual>
      <origin rpy="3.14 1.57 3.14" xyz="-0.27 -0.01 0.05"/>
      <!-- <origin rpy="0 0 0" xyz="-0.125 -0.0 0"/> -->
      <geometry>
        <mesh scale="0.001 0.001 0.001" filename="package://vision60/meshes/femur_rs.STL"/>
        <!-- <box size="0.25 0.044 0.06"/> -->
      </geometry>
      <material name="ctorange"/>
    </visual>
    <collision>
      <origin rpy="0 0 0" xyz="-0.125 0 0"/>
      <geometry>
        <box size="0.25 0.044 0.06"/>
      </geometry>
    </collision>
    <inertial>
      <mass value="0.625"/>
      <inertia ixx="0.0003125" ixy="0" ixz="0" iyy="0.0040625" iyz="0" izz="0.0040625"/>
    </inertial>
  </link>
  <!-- Hip joint. (Motor to upper leg). Joint names are: 0 2 4 6 -->
  <joint name="hipPitch3" type="revolute">
    <parent link="hip3"/>
    <child link="upper3"/>
    <axis xyz="0 -1 0"/>
    <origin xyz="0 -0.068 0"/>
    <!--  rpy="0 -0.3 0" -->
    <limit effort="87.5" lower="-3.14159265359" upper="3.14159265359" velocity="30"/>
    <dynamics damping="0.0" friction="0.0"/>
  </joint>
  <!-- Lower leg -->
  <link name="lower3">
    <visual>
      <origin rpy="0 -1.5707963268 0" xyz="0.29 0.02  -0.02"/>
      <!-- <origin rpy="0 1.5707963268 0" xyz="0.14 0 -0.0355"/> -->
      <geometry>
        <mesh scale="0.001 0.001 0.001" filename="package://vision60/meshes/tibia.STL"/>
        <!-- <cylinder length="0.28" radius="0.011"/> -->
      </geometry>
      <material name="darkgray"/>
    </visual>
    <collision>
      <origin rpy="0 1.5707963268 0" xyz="0.14 0 -0.0355"/>
      <geometry>
        <cylinder length="0.28" radius="0.011"/>
      </geometry>
    </collision>
    <inertial>
      <mass value="0.2"/>
      <inertia ixx="0.00131075" ixy="0" ixz="0" iyy="0.00131075" iyz="0" izz="0.0001"/>
    </inertial>
  </link>
  <!-- Knee joint. Joint names are: 1 3 5 7 -->
  <joint name="knee3" type="revolute">
    <parent link="upper3"/>
    <child link="lower3"/>
    <axis xyz="0 1 0"/>
    <origin xyz="-0.25 0 0"/>
    <!--rpy="0 0.5 0"-->
    <limit effort="87.5" lower="0" upper="3.14159265359" velocity="30"/>
    <dynamics damping="0.0" friction="0.0"/>
  </joint>
  <!-- Toe -->

</robot>
